Traceback (most recent call last):
  File "/home/ubuntu/.local/bin/uvicorn", line 8, in <module>
    sys.exit(main())
             ~~~~^^
  File "/home/ubuntu/.local/lib/python3.13/site-packages/click/core.py", line 1442, in __call__
    return self.main(*args, **kwargs)
           ~~~~~~~~~^^^^^^^^^^^^^^^^^
  File "/home/ubuntu/.local/lib/python3.13/site-packages/click/core.py", line 1363, in main
    rv = self.invoke(ctx)
  File "/home/ubuntu/.local/lib/python3.13/site-packages/click/core.py", line 1226, in invoke
    return ctx.invoke(self.callback, **ctx.params)
           ~~~~~~~~~~^^^^^^^^^^^^^^^^^^^^^^^^^^^^^
  File "/home/ubuntu/.local/lib/python3.13/site-packages/click/core.py", line 794, in invoke
    return callback(*args, **kwargs)
  File "/home/ubuntu/.local/lib/python3.13/site-packages/uvicorn/main.py", line 413, in main
    run(
    ~~~^
        app,
        ^^^^
    ...<45 lines>...
        h11_max_incomplete_event_size=h11_max_incomplete_event_size,
        ^^^^^^^^^^^^^^^^^^^^^^^^^^^^^^^^^^^^^^^^^^^^^^^^^^^^^^^^^^^^
    )
    ^
  File "/home/ubuntu/.local/lib/python3.13/site-packages/uvicorn/main.py", line 580, in run
    server.run()
    ~~~~~~~~~~^^
  File "/home/ubuntu/.local/lib/python3.13/site-packages/uvicorn/server.py", line 67, in run
    return asyncio.run(self.serve(sockets=sockets))
           ~~~~~~~~~~~^^^^^^^^^^^^^^^^^^^^^^^^^^^^^
  File "/usr/lib/python3.13/asyncio/runners.py", line 195, in run
    return runner.run(main)
           ~~~~~~~~~~^^^^^^
  File "/usr/lib/python3.13/asyncio/runners.py", line 118, in run
    return self._loop.run_until_complete(task)
           ~~~~~~~~~~~~~~~~~~~~~~~~~~~~~^^^^^^
  File "/usr/lib/python3.13/asyncio/base_events.py", line 719, in run_until_complete
    return future.result()
           ~~~~~~~~~~~~~^^
  File "/home/ubuntu/.local/lib/python3.13/site-packages/uvicorn/server.py", line 71, in serve
    await self._serve(sockets)
  File "/home/ubuntu/.local/lib/python3.13/site-packages/uvicorn/server.py", line 78, in _serve
    config.load()
    ~~~~~~~~~~~^^
  File "/home/ubuntu/.local/lib/python3.13/site-packages/uvicorn/config.py", line 436, in load
    self.loaded_app = import_from_string(self.app)
                      ~~~~~~~~~~~~~~~~~~^^^^^^^^^^
  File "/home/ubuntu/.local/lib/python3.13/site-packages/uvicorn/importer.py", line 19, in import_from_string
    module = importlib.import_module(module_str)
  File "/usr/lib/python3.13/importlib/__init__.py", line 88, in import_module
    return _bootstrap._gcd_import(name[level:], package, level)
           ~~~~~~~~~~~~~~~~~~~~~~^^^^^^^^^^^^^^^^^^^^^^^^^^^^^^
  File "<frozen importlib._bootstrap>", line 1387, in _gcd_import
  File "<frozen importlib._bootstrap>", line 1360, in _find_and_load
  File "<frozen importlib._bootstrap>", line 1331, in _find_and_load_unlocked
  File "<frozen importlib._bootstrap>", line 935, in _load_unlocked
  File "<frozen importlib._bootstrap_external>", line 1026, in exec_module
  File "<frozen importlib._bootstrap>", line 488, in _call_with_frames_removed
  File "/workspace/backend/app/main.py", line 394, in <module>
    @app.get("/users", response_model=list[UserPublic])
     ~~~~~~~^^^^^^^^^^^^^^^^^^^^^^^^^^^^^^^^^^^^^^^^^^^
  File "/home/ubuntu/.local/lib/python3.13/site-packages/fastapi/routing.py", line 995, in decorator
    self.add_api_route(
    ~~~~~~~~~~~~~~~~~~^
        path,
        ^^^^^
    ...<23 lines>...
        generate_unique_id_function=generate_unique_id_function,
        ^^^^^^^^^^^^^^^^^^^^^^^^^^^^^^^^^^^^^^^^^^^^^^^^^^^^^^^^
    )
    ^
  File "/home/ubuntu/.local/lib/python3.13/site-packages/fastapi/routing.py", line 934, in add_api_route
    route = route_class(
        self.prefix + path,
    ...<24 lines>...
        generate_unique_id_function=current_generate_unique_id,
    )
  File "/home/ubuntu/.local/lib/python3.13/site-packages/fastapi/routing.py", line 555, in __init__
    self.dependant = get_dependant(path=self.path_format, call=self.endpoint)
                     ~~~~~~~~~~~~~^^^^^^^^^^^^^^^^^^^^^^^^^^^^^^^^^^^^^^^^^^^
  File "/home/ubuntu/.local/lib/python3.13/site-packages/fastapi/dependencies/utils.py", line 285, in get_dependant
    param_details = analyze_param(
        param_name=param_name,
    ...<2 lines>...
        is_path_param=is_path_param,
    )
  File "/home/ubuntu/.local/lib/python3.13/site-packages/fastapi/dependencies/utils.py", line 404, in analyze_param
    assert depends is None, (
           ^^^^^^^^^^^^^^^
AssertionError: Cannot specify `Depends` in `Annotated` and default value together for 'db'
